<?xml version='1.0'?>

<robot name="my_bot" xmlns:xacro="http://www.ros.org/wiki/xacro">

  <!-- import plugins for camera and LiDAR defined in the .gazebo file -->
  <!-- my_bot.gazebo file includes the following plugins:
    1. A plugin for the camera sensor.
    2. A plugin for the hokuyo sensor.
    3. A plugin for controlling the wheel joints. -->
<xacro:include filename="$(find slam_project)/urdf/my_bot.gazebo" />

  <link name="robot_footprint"></link>

  <joint name="robot_footprint_joint" type="fixed">
    <origin xyz="0 0 0" rpy="0 0 0" />
    <parent link="robot_footprint"/>
    <child link="chassis" />
  </joint>

  <!-- chassis and caster link -->
  <link name='chassis'>
    <pose>0 0 0.1 0 0 0</pose>

    <inertial>
      <mass value="5.0"/>
      <origin xyz="0.0 0 0" rpy=" 0 0 0"/>
      <inertia
          ixx="0.1" ixy="0" ixz="0"
          iyy="0.1" iyz="0"
          izz="0.1"
      />
    </inertial>

    <collision name='collision'>
      <origin xyz="0 0 0" rpy=" 0 0 0"/>
      <geometry>
        <box size=".4 .2 .1"/>
      </geometry>
    </collision>

    <visual name='chassis_visual'>
      <origin xyz="0 0 0" rpy=" 0 0 0"/>
      <geometry>
        <box size=".4 .2 .1"/>
      </geometry>
    </visual>

    <!-- Front-Left Wheels -->
    <visual name='front_left_wheel_visual'>
      <origin xyz="0.15 -0.15 0" rpy=" 0 1.5707 1.5707"/>
      <geometry>
        <cylinder length="0.05" radius="0.1"/>
      </geometry>
    </visual>
    <collision name='front_left_wheel_collision'>
      <origin xyz="0.15 -0.15 0" rpy=" 0 1.5707 1.5707"/>
      <geometry>
        <cylinder length="0.05" radius="0.099"/>
      </geometry>
    </collision>
    <!-- Front-Right Wheels -->
    <visual name='front_right_wheel_visual'>
      <origin xyz="0.15 0.15 0" rpy=" 0 1.5707 1.5707"/>
      <geometry>
        <cylinder length="0.05" radius="0.1"/>
      </geometry>
    </visual>
    <collision name='front_right_wheel_collision'>
      <origin xyz="0.15 0.15 0" rpy=" 0 1.5707 1.5707"/>
      <geometry>
        <cylinder length="0.05" radius="0.099"/>
      </geometry>
    </collision>

    <!-- Rear-Left Wheels -->
    <visual name='rear_left_wheel_visual'>
      <origin xyz="-0.15 -0.15 0" rpy=" 0 1.5707 1.5707"/>
      <geometry>
        <cylinder length="0.05" radius="0.1"/>
      </geometry>
    </visual>
    <collision name='rear_left_wheel_collision'>
      <origin xyz="-0.15 -0.15 0" rpy=" 0 1.5707 1.5707"/>
      <geometry>
        <cylinder length="0.05" radius="0.099"/>
      </geometry>
    </collision>
    <!-- Rear-Right Wheels -->
    <visual name='rear_right_wheel_visual'>
      <origin xyz="-0.15 0.15 0" rpy=" 0 1.5707 1.5707"/>
      <geometry>
        <cylinder length="0.05" radius="0.1"/>
      </geometry>
    </visual>
    <collision name='rear_right_wheel_collision'>
      <origin xyz="-0.15 0.15 0" rpy=" 0 1.5707 1.5707"/>
      <geometry>
        <cylinder length="0.05" radius="0.099"/>
      </geometry>
    </collision>  

  </link>

   <!-- left-wheel link -->
   <link name='left_wheel'>
     <inertial>
       <mass value="5.0"/>
       <origin xyz="0.0 0 0" rpy=" 0 1.5707 1.5707"/>
       <inertia
           ixx="0.1" ixy="0" ixz="0"
           iyy="0.1" iyz="0"
           izz="0.1"
       />
     </inertial>

     <collision name='left_wheel_collision'>
       <origin xyz="0 0 0" rpy=" 0 1.5707 1.5707"/>
       <geometry>
         <cylinder length="0.05" radius="0.1"/>
       </geometry>
     </collision>

   </link>

   <!-- right-wheel link -->
   <link name='right_wheel'>
     <inertial>
       <mass value="5.0"/>
       <origin xyz="0.0 0 0" rpy=" 0 1.5707 1.5707"/>
       <inertia
           ixx="0.1" ixy="0" ixz="0"
           iyy="0.1" iyz="0"
           izz="0.1"
       />
     </inertial>

     <collision name='right_wheel_collision'>
       <origin xyz="0 0 0" rpy=" 0 1.5707 1.5707"/>
       <geometry>
         <cylinder length="0.05" radius="0.1"/>
       </geometry>
     </collision>

   </link>

  <!-- Camera link -->
  <link name='camera'>

    <inertial>
      <mass value="0.1"/>
      <origin xyz="0 0 0" rpy="0 0 0"/>
      <inertia
          ixx="1e-6" ixy="0" ixz="0"
          iyy="1e-6" iyz="0"
          izz="1e-6"
      />
    </inertial>

    <collision name='camera_collision'>
      <origin xyz="0 0 0" rpy="0 0 0"/>
      <geometry>
	<box size="0.073000 0.276000 0.07200"/>
        <!-- <box size="0.025 0.05 0.05"/> -->
      </geometry>
    </collision>

    <visual name='camera_visual'>
      <origin xyz="0 0 0" rpy="0 0 0"/>
      <geometry>
        <!-- <box size="0.025 0.05 0.05"/> -->
	<mesh filename="package://slam_project/meshes/kinect.dae"/>
      </geometry>
    </visual>

  </link>

  <!-- LiDAR link -->
  <link name='hokuyo'>

    <inertial>
      <mass value="0.1"/>
      <origin xyz="0 0 0" rpy=" 0 0 0"/>
      <inertia
          ixx="1e-6" ixy="0" ixz="0"
          iyy="1e-6" iyz="0"
          izz="1e-6"
      />
    </inertial>

    <collision name='hokuyo_collision'>
      <origin xyz="0 0 0" rpy=" 0 0 0"/>
      <geometry>
        <box size="0.1 0.1 0.1"/>
      </geometry>
    </collision>

    <visual name='hokuyo_visual'>
      <origin xyz="0 0 0" rpy=" 0 0 0"/>
      <geometry>
        <mesh filename="package://slam_project/meshes/hokuyo.dae"/>
      </geometry>
    </visual>

  </link>

  <!-- left-wheel joint -->
  <joint name="left_wheel_hinge" type="continuous">
    <origin xyz="0 0.15 0" rpy="0 0 0"/>
    <child link="left_wheel"/>
    <parent link="chassis"/>
    <axis xyz="0 1 0" rpy="0 0 0"/>
    <limit effort="10000" velocity="1000"/>
    <dynamics damping="1.0" friction="1.0"/>
  </joint>
  <!-- right-wheel joint -->
  <joint name="right_wheel_hinge" type="continuous" >
    <origin xyz="0 -0.15 0" rpy="0 0 0"/>
    <child link="right_wheel"/>
    <parent link="chassis"/>
    <axis xyz="0 1 0" rpy="0 0 0"/>
    <limit effort="10000" velocity="1000"/>
    <dynamics damping="1.0" friction="1.0"/>
  </joint>

  <!-- Camera joint -->
  <joint name="camera_joint" type="fixed">
    <origin xyz="0.2 0 0" rpy="0 0 0"/>
    <child link="camera"/>
    <parent link="chassis"/>
    <limit effort="10000" velocity="1000"/>
    <dynamics damping="1.0" friction="1.0"/>
  </joint>
  <!-- RGBD Link & Joint -->
  <link name="camera_rgbd_frame"/>
  <joint name="rgbd_camera_joint" type="fixed" >
    <origin xyz="0.2 0 0" rpy="-1.5707 0 -1.5707"/>
    <child link="camera_rgbd_frame"/>
    <parent link="camera"/>
  </joint>

  <!-- LiDAR joint -->
  <joint name="hokuyo_joint" type="fixed">
    <origin xyz="0.15 0 0.1" rpy="0 0 0"/>
    <child link="hokuyo"/>
    <parent link="chassis"/>
    <axis xyz="0 1 0" rpy="0 0 0"/>
    <limit effort="10000" velocity="1000"/>
    <joint_properties damping="1.0" friction="1.0"/>
  </joint>


</robot>
